[2022-11-08T21:06:57Z] DEBUG    - Logging set up successfully
[2022-11-08T21:06:57Z] DEBUG    - Running test: Namespace(version=False, subparser_name='test', command=<function test at 0x125533eb0>, verbose=0, endpoint='http://127.0.0.1:3001', function_name='TypeFunction', region='us-east-1', role_arn=None, cloudformation_endpoint_url=None, enforce_timeout='30', log_group_name=None, log_role_arn=None, passed_to_pytest=['-k', 'create_read'], docker_image=None)
[2022-11-08T21:06:57Z] DEBUG    - Root directory: /Users/govardhanpagidi/workspace/mongo/cfn/repo/mongodb/mongodbatlas-cloudformation-resources/cfn-resources
[2022-11-08T21:06:57Z] DEBUG    - Loading project file '/Users/govardhanpagidi/workspace/mongo/cfn/repo/mongodb/mongodbatlas-cloudformation-resources/cfn-resources/.rpdk-config'
[2022-11-08T21:06:57Z] DEBUG    - Project file /Users/govardhanpagidi/workspace/mongo/cfn/repo/mongodb/mongodbatlas-cloudformation-resources/cfn-resources/.rpdk-config not found. Have you run 'init' or in a wrong directory?
Traceback (most recent call last):
  File "/Library/Frameworks/Python.framework/Versions/3.10/lib/python3.10/site-packages/rpdk/core/project.py", line 562, in load
    self.load_settings()
  File "/Library/Frameworks/Python.framework/Versions/3.10/lib/python3.10/site-packages/rpdk/core/project.py", line 234, in load_settings
    with self.settings_path.open("r", encoding="utf-8") as f:
  File "/Library/Frameworks/Python.framework/Versions/3.10/lib/python3.10/pathlib.py", line 1119, in open
    return self._accessor.open(self, mode, buffering, encoding, errors,
FileNotFoundError: [Errno 2] No such file or directory: '/Users/govardhanpagidi/workspace/mongo/cfn/repo/mongodb/mongodbatlas-cloudformation-resources/cfn-resources/.rpdk-config'
[2022-11-08T21:06:57Z] DEBUG    - Caught exit recommendation
Traceback (most recent call last):
  File "/Library/Frameworks/Python.framework/Versions/3.10/lib/python3.10/site-packages/rpdk/core/project.py", line 562, in load
    self.load_settings()
  File "/Library/Frameworks/Python.framework/Versions/3.10/lib/python3.10/site-packages/rpdk/core/project.py", line 234, in load_settings
    with self.settings_path.open("r", encoding="utf-8") as f:
  File "/Library/Frameworks/Python.framework/Versions/3.10/lib/python3.10/pathlib.py", line 1119, in open
    return self._accessor.open(self, mode, buffering, encoding, errors,
FileNotFoundError: [Errno 2] No such file or directory: '/Users/govardhanpagidi/workspace/mongo/cfn/repo/mongodb/mongodbatlas-cloudformation-resources/cfn-resources/.rpdk-config'

The above exception was the direct cause of the following exception:

Traceback (most recent call last):
  File "/Library/Frameworks/Python.framework/Versions/3.10/lib/python3.10/site-packages/rpdk/core/cli.py", line 100, in main
    args.command(args)
  File "/Library/Frameworks/Python.framework/Versions/3.10/lib/python3.10/site-packages/rpdk/core/test.py", line 354, in test
    project.load()
  File "/Library/Frameworks/Python.framework/Versions/3.10/lib/python3.10/site-packages/rpdk/core/project.py", line 564, in load
    self._raise_invalid_project(
  File "/Library/Frameworks/Python.framework/Versions/3.10/lib/python3.10/site-packages/rpdk/core/project.py", line 229, in _raise_invalid_project
    raise InvalidProjectError(msg) from e
rpdk.core.exceptions.InvalidProjectError: Project file /Users/govardhanpagidi/workspace/mongo/cfn/repo/mongodb/mongodbatlas-cloudformation-resources/cfn-resources/.rpdk-config not found. Have you run 'init' or in a wrong directory?
[2022-11-08T21:06:57Z] CRITICAL - Project file /Users/govardhanpagidi/workspace/mongo/cfn/repo/mongodb/mongodbatlas-cloudformation-resources/cfn-resources/.rpdk-config not found. Have you run 'init' or in a wrong directory?
[2022-11-09T16:53:55Z] DEBUG    - Logging set up successfully
[2022-11-09T16:53:55Z] DEBUG    - Running generate: Namespace(version=False, subparser_name='generate', command=<function generate at 0x12648ca60>, verbose=0, endpoint_url=None, region=None, target_schemas=[])
[2022-11-09T16:53:55Z] DEBUG    - Root directory: /Users/govardhanpagidi/workspace/mongo/cfn/repo/mongodb/mongodbatlas-cloudformation-resources/cfn-resources
[2022-11-09T16:53:55Z] DEBUG    - Loading project file '/Users/govardhanpagidi/workspace/mongo/cfn/repo/mongodb/mongodbatlas-cloudformation-resources/cfn-resources/.rpdk-config'
[2022-11-09T16:53:55Z] DEBUG    - Project file /Users/govardhanpagidi/workspace/mongo/cfn/repo/mongodb/mongodbatlas-cloudformation-resources/cfn-resources/.rpdk-config not found. Have you run 'init' or in a wrong directory?
Traceback (most recent call last):
  File "/Library/Frameworks/Python.framework/Versions/3.10/lib/python3.10/site-packages/rpdk/core/project.py", line 562, in load
    self.load_settings()
  File "/Library/Frameworks/Python.framework/Versions/3.10/lib/python3.10/site-packages/rpdk/core/project.py", line 234, in load_settings
    with self.settings_path.open("r", encoding="utf-8") as f:
  File "/Library/Frameworks/Python.framework/Versions/3.10/lib/python3.10/pathlib.py", line 1119, in open
    return self._accessor.open(self, mode, buffering, encoding, errors,
FileNotFoundError: [Errno 2] No such file or directory: '/Users/govardhanpagidi/workspace/mongo/cfn/repo/mongodb/mongodbatlas-cloudformation-resources/cfn-resources/.rpdk-config'
[2022-11-09T16:53:55Z] DEBUG    - Caught exit recommendation
Traceback (most recent call last):
  File "/Library/Frameworks/Python.framework/Versions/3.10/lib/python3.10/site-packages/rpdk/core/project.py", line 562, in load
    self.load_settings()
  File "/Library/Frameworks/Python.framework/Versions/3.10/lib/python3.10/site-packages/rpdk/core/project.py", line 234, in load_settings
    with self.settings_path.open("r", encoding="utf-8") as f:
  File "/Library/Frameworks/Python.framework/Versions/3.10/lib/python3.10/pathlib.py", line 1119, in open
    return self._accessor.open(self, mode, buffering, encoding, errors,
FileNotFoundError: [Errno 2] No such file or directory: '/Users/govardhanpagidi/workspace/mongo/cfn/repo/mongodb/mongodbatlas-cloudformation-resources/cfn-resources/.rpdk-config'

The above exception was the direct cause of the following exception:

Traceback (most recent call last):
  File "/Library/Frameworks/Python.framework/Versions/3.10/lib/python3.10/site-packages/rpdk/core/cli.py", line 100, in main
    args.command(args)
  File "/Library/Frameworks/Python.framework/Versions/3.10/lib/python3.10/site-packages/rpdk/core/generate.py", line 14, in generate
    project.load()
  File "/Library/Frameworks/Python.framework/Versions/3.10/lib/python3.10/site-packages/rpdk/core/project.py", line 564, in load
    self._raise_invalid_project(
  File "/Library/Frameworks/Python.framework/Versions/3.10/lib/python3.10/site-packages/rpdk/core/project.py", line 229, in _raise_invalid_project
    raise InvalidProjectError(msg) from e
rpdk.core.exceptions.InvalidProjectError: Project file /Users/govardhanpagidi/workspace/mongo/cfn/repo/mongodb/mongodbatlas-cloudformation-resources/cfn-resources/.rpdk-config not found. Have you run 'init' or in a wrong directory?
[2022-11-09T16:53:55Z] CRITICAL - Project file /Users/govardhanpagidi/workspace/mongo/cfn/repo/mongodb/mongodbatlas-cloudformation-resources/cfn-resources/.rpdk-config not found. Have you run 'init' or in a wrong directory?
